<?xml version="1.0" encoding="UTF-8"?>
<!-- Generated by org.testng.reporters.JUnitReportReporter -->
<testsuite hostname="LAPTOP-8UKHKL7O" failures="1" tests="5" name="com.bank.tests.LoginTest" time="4.380" errors="1" timestamp="2024-10-03T16:53:16 IST" skipped="1">
  <testcase classname="com.bank.tests.LoginTest" name="skipped" time="0.000">
    <skipped/>
  </testcase> <!-- skipped -->
  <system-out/>
  <testcase classname="com.bank.tests.LoginTest" name="loginWithValidCredentials" time="2.657"/>
  <system-out/>
  <testcase classname="com.bank.tests.LoginTest" name="loginWithInvalidCredentials" time="1.691"/>
  <system-out/>
  <testcase classname="com.bank.tests.LoginTest" name="failure" time="0.028">
    <error message="unexpected alert open: {Alert text : User is not valid}
  (Session info: MicrosoftEdge=129.0.2792.65): User is not valid
Build info: version: &#039;4.21.0&#039;, revision: &#039;79ed462ef4&#039;
System info: os.name: &#039;Windows 11&#039;, os.arch: &#039;amd64&#039;, os.version: &#039;10.0&#039;, java.version: &#039;21.0.2&#039;
Driver info: org.openqa.selenium.edge.EdgeDriver
Command: [b537b363125f48224421ef373f06bd17, screenshot {}]
Capabilities {acceptInsecureCerts: false, browserName: MicrosoftEdge, browserVersion: 129.0.2792.65, fedcm:accounts: true, ms:edgeOptions: {debuggerAddress: localhost:64708}, msedge: {msedgedriverVersion: 129.0.2792.65 (7eae50a1bc8e..., userDataDir: C:\Users\patel\AppData\Loca...}, networkConnectionEnabled: false, pageLoadStrategy: normal, platformName: windows, proxy: Proxy(), se:cdp: ws://localhost:64708/devtoo..., se:cdpVersion: 129.0.2792.65, setWindowRect: true, strictFileInteractability: false, timeouts: {implicit: 0, pageLoad: 300000, script: 30000}, unhandledPromptBehavior: dismiss and notify, webauthn:extension:credBlob: true, webauthn:extension:largeBlob: true, webauthn:extension:minPinLength: true, webauthn:extension:prf: true, webauthn:virtualAuthenticators: true}
Session ID: b537b363125f48224421ef373f06bd17" type="org.openqa.selenium.UnhandledAlertException">
      <![CDATA[org.openqa.selenium.UnhandledAlertException: unexpected alert open: {Alert text : User is not valid}
  (Session info: MicrosoftEdge=129.0.2792.65): User is not valid
Build info: version: '4.21.0', revision: '79ed462ef4'
System info: os.name: 'Windows 11', os.arch: 'amd64', os.version: '10.0', java.version: '21.0.2'
Driver info: org.openqa.selenium.edge.EdgeDriver
Command: [b537b363125f48224421ef373f06bd17, screenshot {}]
Capabilities {acceptInsecureCerts: false, browserName: MicrosoftEdge, browserVersion: 129.0.2792.65, fedcm:accounts: true, ms:edgeOptions: {debuggerAddress: localhost:64708}, msedge: {msedgedriverVersion: 129.0.2792.65 (7eae50a1bc8e..., userDataDir: C:\Users\patel\AppData\Loca...}, networkConnectionEnabled: false, pageLoadStrategy: normal, platformName: windows, proxy: Proxy(), se:cdp: ws://localhost:64708/devtoo..., se:cdpVersion: 129.0.2792.65, setWindowRect: true, strictFileInteractability: false, timeouts: {implicit: 0, pageLoad: 300000, script: 30000}, unhandledPromptBehavior: dismiss and notify, webauthn:extension:credBlob: true, webauthn:extension:largeBlob: true, webauthn:extension:minPinLength: true, webauthn:extension:prf: true, webauthn:virtualAuthenticators: true}
Session ID: b537b363125f48224421ef373f06bd17
at org.openqa.selenium.remote.codec.w3c.W3CHttpResponseCodec.decode(W3CHttpResponseCodec.java:136)
at org.openqa.selenium.remote.codec.w3c.W3CHttpResponseCodec.decode(W3CHttpResponseCodec.java:50)
at org.openqa.selenium.remote.HttpCommandExecutor.execute(HttpCommandExecutor.java:190)
at org.openqa.selenium.remote.service.DriverCommandExecutor.invokeExecute(DriverCommandExecutor.java:216)
at org.openqa.selenium.remote.service.DriverCommandExecutor.execute(DriverCommandExecutor.java:174)
at org.openqa.selenium.remote.RemoteWebDriver.execute(RemoteWebDriver.java:518)
at org.openqa.selenium.remote.RemoteWebDriver.execute(RemoteWebDriver.java:591)
at org.openqa.selenium.remote.RemoteWebDriver.execute(RemoteWebDriver.java:595)
at org.openqa.selenium.remote.RemoteWebDriver.getScreenshotAs(RemoteWebDriver.java:321)
at com.bank.utilities.ScreenshotUtility.captureScreenshot(ScreenshotUtility.java:19)
at com.bank.utilities.ExtentReportsManager.onTestFailure(ExtentReportsManager.java:59)
at org.testng.internal.TestListenerHelper.runTestListeners(TestListenerHelper.java:99)
at org.testng.internal.invokers.TestInvoker.runTestResultListener(TestInvoker.java:277)
at org.testng.internal.invokers.TestInvoker.invokeMethod(TestInvoker.java:764)
at org.testng.internal.invokers.TestInvoker.invokeTestMethod(TestInvoker.java:221)
at org.testng.internal.invokers.MethodRunner.runInSequence(MethodRunner.java:50)
at org.testng.internal.invokers.TestInvoker$MethodInvocationAgent.invoke(TestInvoker.java:969)
at org.testng.internal.invokers.TestInvoker.invokeTestMethods(TestInvoker.java:194)
at org.testng.internal.invokers.TestMethodWorker.invokeTestMethods(TestMethodWorker.java:148)
at org.testng.internal.invokers.TestMethodWorker.run(TestMethodWorker.java:128)
at java.base/java.util.ArrayList.forEach(ArrayList.java:1596)
at org.testng.TestRunner.privateRun(TestRunner.java:829)
at org.testng.TestRunner.run(TestRunner.java:602)
at org.testng.SuiteRunner.runTest(SuiteRunner.java:437)
at org.testng.SuiteRunner.runSequentially(SuiteRunner.java:431)
at org.testng.SuiteRunner.privateRun(SuiteRunner.java:391)
at org.testng.SuiteRunner.run(SuiteRunner.java:330)
at org.testng.SuiteRunnerWorker.runSuite(SuiteRunnerWorker.java:52)
at org.testng.SuiteRunnerWorker.run(SuiteRunnerWorker.java:95)
at org.testng.TestNG.runSuitesSequentially(TestNG.java:1256)
at org.testng.TestNG.runSuitesLocally(TestNG.java:1176)
at org.testng.TestNG.runSuites(TestNG.java:1099)
at org.testng.TestNG.run(TestNG.java:1067)
at org.testng.remote.AbstractRemoteTestNG.run(AbstractRemoteTestNG.java:115)
at org.testng.remote.RemoteTestNG.initAndRun(RemoteTestNG.java:251)
at org.testng.remote.RemoteTestNG.main(RemoteTestNG.java:77)
]]>
    </error>
  </testcase> <!-- failure -->
  <system-out/>
  <testcase classname="com.bank.tests.LoginTest" name="failure2" time="0.004">
    <failure message="expected [true] but found [false]" type="java.lang.AssertionError">
      <![CDATA[java.lang.AssertionError: expected [true] but found [false]
at org.testng.Assert.fail(Assert.java:110)
at org.testng.Assert.failNotEquals(Assert.java:1577)
at org.testng.Assert.assertTrue(Assert.java:56)
at org.testng.Assert.assertTrue(Assert.java:66)
at com.bank.tests.LoginTest.failure2(LoginTest.java:58)
at java.base/jdk.internal.reflect.DirectMethodHandleAccessor.invoke(DirectMethodHandleAccessor.java:103)
at java.base/java.lang.reflect.Method.invoke(Method.java:580)
at org.testng.internal.invokers.MethodInvocationHelper.invokeMethod(MethodInvocationHelper.java:139)
at org.testng.internal.invokers.TestInvoker.invokeMethod(TestInvoker.java:677)
at org.testng.internal.invokers.TestInvoker.invokeTestMethod(TestInvoker.java:221)
at org.testng.internal.invokers.MethodRunner.runInSequence(MethodRunner.java:50)
at org.testng.internal.invokers.TestInvoker$MethodInvocationAgent.invoke(TestInvoker.java:969)
at org.testng.internal.invokers.TestInvoker.invokeTestMethods(TestInvoker.java:194)
at org.testng.internal.invokers.TestMethodWorker.invokeTestMethods(TestMethodWorker.java:148)
at org.testng.internal.invokers.TestMethodWorker.run(TestMethodWorker.java:128)
at java.base/java.util.ArrayList.forEach(ArrayList.java:1596)
at org.testng.TestRunner.privateRun(TestRunner.java:829)
at org.testng.TestRunner.run(TestRunner.java:602)
at org.testng.SuiteRunner.runTest(SuiteRunner.java:437)
at org.testng.SuiteRunner.runSequentially(SuiteRunner.java:431)
at org.testng.SuiteRunner.privateRun(SuiteRunner.java:391)
at org.testng.SuiteRunner.run(SuiteRunner.java:330)
at org.testng.SuiteRunnerWorker.runSuite(SuiteRunnerWorker.java:52)
at org.testng.SuiteRunnerWorker.run(SuiteRunnerWorker.java:95)
at org.testng.TestNG.runSuitesSequentially(TestNG.java:1256)
at org.testng.TestNG.runSuitesLocally(TestNG.java:1176)
at org.testng.TestNG.runSuites(TestNG.java:1099)
at org.testng.TestNG.run(TestNG.java:1067)
at org.testng.remote.AbstractRemoteTestNG.run(AbstractRemoteTestNG.java:115)
at org.testng.remote.RemoteTestNG.initAndRun(RemoteTestNG.java:251)
at org.testng.remote.RemoteTestNG.main(RemoteTestNG.java:77)
]]>
    </failure>
  </testcase> <!-- failure2 -->
  <system-out/>
</testsuite> <!-- com.bank.tests.LoginTest -->
